<?xml version="1.0" ?>
<robot name="JinBot">
  <link name="base_link">
    <inertial>
      <origin xyz="0.000741213 -1.89163e-05 -0.00853678" rpy="0 0 0" />
      <mass value="1.47836" />
      <inertia ixx="0.0060089" ixy="3.04111e-07" ixz="-2.55395e-06" iyy="0.00120553" iyz="-1.18675e-06" izz="0.00686201" />
    </inertial>

    <visual>
      <origin xyz="0.000993584 -0.0600788 -0.039" rpy="-1.5708 1.5708 0" />
      <geometry>
        <mesh filename="assets/dm_j8006_2ec_v1_1.stl" />
      </geometry>
      <material name="dm_j8006_2ec_v1_1_material">
        <color rgba="0.301961 0.301961 0.301961 1" />
      </material>
    </visual>
    <collision>
      <origin xyz="0.000993584 -0.0600788 -0.039" rpy="-1.5708 1.5708 0" />
      <geometry>
        <mesh filename="assets/dm_j8006_2ec_v1_1.stl" />
      </geometry>
    </collision>

    <visual>
      <origin xyz="0.000993584 0.0599212 -0.039" rpy="-1.5708 1.5708 0" />
      <geometry>
        <mesh filename="assets/dm_j8006_2ec_v1_1.stl" />
      </geometry>
      <material name="dm_j8006_2ec_v1_1_2_material">
        <color rgba="0.301961 0.301961 0.301961 1" />
      </material>
    </visual>
    <collision>
      <origin xyz="0.000993584 0.0599212 -0.039" rpy="-1.5708 1.5708 0" />
      <geometry>
        <mesh filename="assets/dm_j8006_2ec_v1_1.stl" />
      </geometry>
    </collision>

    <visual>
      <origin xyz="0.000152274 -0.00449984 -0.0265" rpy="-2.0944 0 1.5708" />
      <geometry>
        <mesh filename="assets/part_2.stl" />
      </geometry>
      <material name="part_2_material">
        <color rgba="0.831373 0.686275 0.215686 1" />
      </material>
    </visual>
    <collision>
      <origin xyz="0.000152274 -0.00449984 -0.0265" rpy="-2.0944 0 1.5708" />
      <geometry>
        <mesh filename="assets/part_2.stl" />
      </geometry>
    </collision>
  </link>

  <link name="r_hip_yaw_link">
    <inertial>
      <origin xyz="0.00294504 1.90807e-05 -0.0728428" rpy="0 0 0" />
      <mass value="0.784517" />
      <inertia ixx="0.00134131" ixy="4.05371e-07" ixz="-2.54902e-06" iyy="0.000929225" iyz="-1.65932e-07" izz="0.000598211" />
    </inertial>

    <visual>
      <origin xyz="0.037 0 -0.0715" rpy="-0 0 0" />
      <geometry>
        <mesh filename="assets/dm_j8006_2ec_v1_1.stl" />
      </geometry>
      <material name="dm_j8006_2ec_v1_1_3_material">
        <color rgba="0.301961 0.301961 0.301961 1" />
      </material>
    </visual>
    <collision>
      <origin xyz="0.037 0 -0.0715" rpy="-0 0 0" />
      <geometry>
        <mesh filename="assets/dm_j8006_2ec_v1_1.stl" />
      </geometry>
    </collision>

    <visual>
      <origin xyz="-6.40646e-05 0.0645 -0.005" rpy="-2.0944 0 -1.5708" />
      <geometry>
        <mesh filename="assets/part_1.stl" />
      </geometry>
      <material name="part_1_material">
        <color rgba="0.784314 0.0392157 0.0392157 1" />
      </material>
    </visual>
    <collision>
      <origin xyz="-6.40646e-05 0.0645 -0.005" rpy="-2.0944 0 -1.5708" />
      <geometry>
        <mesh filename="assets/part_1.stl" />
      </geometry>
    </collision>
  </link>

  <link name="r_hip_roll_link">
    <inertial>
      <origin xyz="-0.0185439 -5.89571e-05 0.0116465" rpy="0 0 0" />
      <mass value="0.127662" />
      <inertia ixx="5.62809e-05" ixy="-5.21e-10" ixz="-8.49385e-06" iyy="0.000159752" iyz="-4.9e-10" izz="0.000206022" />
    </inertial>

    <visual>
      <origin xyz="-0.0645 -5.91774e-05 0.005" rpy="1.0472 -0 -0" />
      <geometry>
        <mesh filename="assets/part_1__2.stl" />
      </geometry>
      <material name="part_1_2_material">
        <color rgba="0.831373 0.686275 0.215686 1" />
      </material>
    </visual>
    <collision>
      <origin xyz="-0.0645 -5.91774e-05 0.005" rpy="1.0472 -0 -0" />
      <geometry>
        <mesh filename="assets/part_1__2.stl" />
      </geometry>
    </collision>
  </link>

  <link name="r_hip_pitch_link">
    <inertial>
      <origin xyz="3.55558e-05 -0.0600129 0.0182689" rpy="0 0 0" />
      <mass value="1.70514" />
      <inertia ixx="0.00680111" ixy="-5.99e-10" ixz="-1.21692e-06" iyy="0.00159839" iyz="4.44237e-07" izz="0.00788052" />
    </inertial>

    <visual>
      <origin xyz="0 -0 0.0025" rpy="-0 -0 -0" />
      <geometry>
        <mesh filename="assets/dm_j8006_2ec_v1_1__2.stl" />
      </geometry>
      <material name="dm_j8006_2ec_v1_1_4_material">
        <color rgba="0.301961 0.301961 0.301961 1" />
      </material>
    </visual>
    <collision>
      <origin xyz="0 -0 0.0025" rpy="-0 -0 -0" />
      <geometry>
        <mesh filename="assets/dm_j8006_2ec_v1_1__2.stl" />
      </geometry>
    </collision>

    <visual>
      <origin xyz="0 -0 0.0025" rpy="-0 -0 -0" />
      <geometry>
        <mesh filename="assets/dm_j8006_2ec_v1_1__3.stl" />
      </geometry>
      <material name="dm_j8006_2ec_v1_1_5_material">
        <color rgba="0.301961 0.301961 0.301961 1" />
      </material>
    </visual>
    <collision>
      <origin xyz="0 -0 0.0025" rpy="-0 -0 -0" />
      <geometry>
        <mesh filename="assets/dm_j8006_2ec_v1_1__3.stl" />
      </geometry>
    </collision>

    <visual>
      <origin xyz="0 -0 0.0025" rpy="-0 -0 -0" />
      <geometry>
        <mesh filename="assets/part_1__3.stl" />
      </geometry>
      <material name="part_1_3_material">
        <color rgba="0.784314 0.0392157 0.0392157 1" />
      </material>
    </visual>
    <collision>
      <origin xyz="0 -0 0.0025" rpy="-0 -0 -0" />
      <geometry>
        <mesh filename="assets/part_1__3.stl" />
      </geometry>
    </collision>

    <visual>
      <origin xyz="8.12448e-06 -0.120096 0.0025" rpy="0 -0 3.14159" />
      <geometry>
        <mesh filename="assets/part_2__2.stl" />
      </geometry>
      <material name="part_2_2_material">
        <color rgba="0.831373 0.686275 0.215686 1" />
      </material>
    </visual>
    <collision>
      <origin xyz="8.12448e-06 -0.120096 0.0025" rpy="0 -0 3.14159" />
      <geometry>
        <mesh filename="assets/part_2__2.stl" />
      </geometry>
    </collision>
  </link>

  <link name="r_knee_pitch_link">
    <inertial>
      <origin xyz="5.76101e-05 -0.125592 0.00177693" rpy="0 0 0" />
      <mass value="0.6749" />
      <inertia ixx="0.0015932" ixy="9.63242e-07" ixz="6.26384e-07" iyy="0.000391518" iyz="0.000133224" izz="0.0018395" />
    </inertial>

    <visual>
      <origin xyz="0 -0.16 0.018" rpy="-3.14159 -0 0.523599" />
      <geometry>
        <mesh filename="assets/dm_j6006_2ec.stl" />
      </geometry>
      <material name="dm_j6006_2ec_material">
        <color rgba="0.301961 0.301961 0.301961 1" />
      </material>
    </visual>
    <collision>
      <origin xyz="0 -0.16 0.018" rpy="-3.14159 -0 0.523599" />
      <geometry>
        <mesh filename="assets/dm_j6006_2ec.stl" />
      </geometry>
    </collision>

    <visual>
      <origin xyz="0 -0.16 0.018" rpy="3.14159 -0 -0.523599" />
      <geometry>
        <mesh filename="assets/part_2__3.stl" />
      </geometry>
      <material name="part_2_3_material">
        <color rgba="0.784314 0.0392157 0.0392157 1" />
      </material>
    </visual>
    <collision>
      <origin xyz="0 -0.16 0.018" rpy="3.14159 -0 -0.523599" />
      <geometry>
        <mesh filename="assets/part_2__3.stl" />
      </geometry>
    </collision>
  </link>

  <link name="r_ankle_pitch_link">
    <inertial>
      <origin xyz="0 -0.0388582 -0.00340315" rpy="0 0 0" />
      <mass value="0.20135" />
      <inertia ixx="0.000100178" ixy="0" ixz="0" iyy="0.000265009" iyz="-1.93066e-05" izz="0.000311964" />
    </inertial>

    <visual>
      <origin xyz="0 0.000137091 -0.0015" rpy="-3.14159 -0 0" />
      <geometry>
        <mesh filename="assets/part_1__4.stl" />
      </geometry>
      <material name="part_1_4_material">
        <color rgba="0.831373 0.686275 0.215686 1" />
      </material>
    </visual>
    <collision>
      <origin xyz="0 0.000137091 -0.0015" rpy="-3.14159 -0 0" />
      <geometry>
        <mesh filename="assets/part_1__4.stl" />
      </geometry>
    </collision>
  </link>

  <joint name="r_ankle_pitch" type="revolute">
    <origin xyz="6.85453e-05 -0.160119 0.0195" rpy="0 0 0" />
    <parent link="r_knee_pitch_link" />
    <child link="r_ankle_pitch_link" />
    <axis xyz="0 0 1" />
    <limit effort="10" velocity="10" lower="-0.523599" upper="0.523599" />
  </joint>

  <joint name="r_knee_pitch" type="revolute">
    <origin xyz="-0 -0.12 0" rpy="0 -0 0" />
    <parent link="r_hip_pitch_link" />
    <child link="r_knee_pitch_link" />
    <axis xyz="0 0 1" />
    <limit effort="10" velocity="10" lower="0" upper="1.74533" />
  </joint>

  <joint name="r_hip_pitch" type="revolute">
    <origin xyz="-0.082 -5.91774e-05 0.00460127" rpy="-0 -1.5708 0" />
    <parent link="r_hip_roll_link" />
    <child link="r_hip_pitch_link" />
    <axis xyz="0 0 1" />
    <limit effort="10" velocity="10" lower="-0.872665" upper="0.523599" />
  </joint>

  <joint name="r_hip_roll" type="revolute">
    <origin xyz="0.0195 0 -0.0715" rpy="1.5708 0 1.5708" />
    <parent link="r_hip_yaw_link" />
    <child link="r_hip_roll_link" />
    <axis xyz="0 0 1" />
    <limit effort="10" velocity="10" lower="-0.349066" upper="0.349066" />
  </joint>

  <joint name="r_hip_yaw" type="revolute">
    <origin xyz="0.000993584 -0.0600788 -0.0215" rpy="0 0 0" />
    <parent link="base_link" />
    <child link="r_hip_yaw_link" />
    <axis xyz="0 0 1" />
    <limit effort="10" velocity="10" lower="-0.523599" upper="0.523599" />
  </joint>

  <link name="l_hip_yaw_link">
    <inertial>
      <origin xyz="0.00294504 -0.000615649 -0.0728982" rpy="0 0 0" />
      <mass value="0.784517" />
      <inertia ixx="0.00134132" ixy="4.55335e-07" ixz="-2.54466e-06" iyy="0.000929104" iyz="5.17925e-07" izz="0.000598337" />
    </inertial>

    <visual>
      <origin xyz="0.037 -0.000905374 -0.071579" rpy="0 0 -0" />
      <geometry>
        <mesh filename="assets/dm_j8006_2ec_v1_1.stl" />
      </geometry>
      <material name="dm_j8006_2ec_v1_1_6_material">
        <color rgba="0.301961 0.301961 0.301961 1" />
      </material>
    </visual>
    <collision>
      <origin xyz="0.037 -0.000905374 -0.071579" rpy="0 0 -0" />
      <geometry>
        <mesh filename="assets/dm_j8006_2ec_v1_1.stl" />
      </geometry>
    </collision>

    <visual>
      <origin xyz="-6.40646e-05 0.0645 -0.005" rpy="-2.0944 -0 -1.5708" />
      <geometry>
        <mesh filename="assets/part_1.stl" />
      </geometry>
      <material name="part_1_5_material">
        <color rgba="0.784314 0.0392157 0.0392157 1" />
      </material>
    </visual>
    <collision>
      <origin xyz="-6.40646e-05 0.0645 -0.005" rpy="-2.0944 -0 -1.5708" />
      <geometry>
        <mesh filename="assets/part_1.stl" />
      </geometry>
    </collision>
  </link>

  <link name="l_hip_roll_link">
    <inertial>
      <origin xyz="0.0185439 5.89571e-05 0.0116465" rpy="0 0 0" />
      <mass value="0.127662" />
      <inertia ixx="5.62809e-05" ixy="-5.21e-10" ixz="8.49385e-06" iyy="0.000159752" iyz="4.9e-10" izz="0.000206022" />
    </inertial>

    <visual>
      <origin xyz="0.0645 5.91774e-05 0.005" rpy="1.0472 0 3.14159" />
      <geometry>
        <mesh filename="assets/part_1__2.stl" />
      </geometry>
      <material name="part_1_6_material">
        <color rgba="0.831373 0.686275 0.215686 1" />
      </material>
    </visual>
    <collision>
      <origin xyz="0.0645 5.91774e-05 0.005" rpy="1.0472 0 3.14159" />
      <geometry>
        <mesh filename="assets/part_1__2.stl" />
      </geometry>
    </collision>
  </link>

  <link name="l_hip_pitch_link">
    <inertial>
      <origin xyz="-3.44619e-05 0.06 0.0182689" rpy="0 0 0" />
      <mass value="1.70514" />
      <inertia ixx="0.00680111" ixy="3e-12" ixz="1.17918e-06" iyy="0.00159839" iyz="-1.31e-10" izz="0.00788052" />
    </inertial>

    <visual>
      <origin xyz="-0 0 0.0025" rpy="0 0 -3.14159" />
      <geometry>
        <mesh filename="assets/dm_j8006_2ec_v1_1__2.stl" />
      </geometry>
      <material name="dm_j8006_2ec_v1_1_7_material">
        <color rgba="0.301961 0.301961 0.301961 1" />
      </material>
    </visual>
    <collision>
      <origin xyz="-0 0 0.0025" rpy="0 0 -3.14159" />
      <geometry>
        <mesh filename="assets/dm_j8006_2ec_v1_1__2.stl" />
      </geometry>
    </collision>

    <visual>
      <origin xyz="-0 0.12 0.0025" rpy="-0 -0 0" />
      <geometry>
        <mesh filename="assets/part_2__2.stl" />
      </geometry>
      <material name="part_2_4_material">
        <color rgba="0.831373 0.686275 0.215686 1" />
      </material>
    </visual>
    <collision>
      <origin xyz="-0 0.12 0.0025" rpy="-0 -0 0" />
      <geometry>
        <mesh filename="assets/part_2__2.stl" />
      </geometry>
    </collision>

    <visual>
      <origin xyz="-0 0 0.0025" rpy="0 0 -3.14159" />
      <geometry>
        <mesh filename="assets/part_1__3.stl" />
      </geometry>
      <material name="part_1_7_material">
        <color rgba="0.784314 0.0392157 0.0392157 1" />
      </material>
    </visual>
    <collision>
      <origin xyz="-0 0 0.0025" rpy="0 0 -3.14159" />
      <geometry>
        <mesh filename="assets/part_1__3.stl" />
      </geometry>
    </collision>

    <visual>
      <origin xyz="-0 0 0.0025" rpy="0 0 -3.14159" />
      <geometry>
        <mesh filename="assets/dm_j8006_2ec_v1_1__3.stl" />
      </geometry>
      <material name="dm_j8006_2ec_v1_1_8_material">
        <color rgba="0.301961 0.301961 0.301961 1" />
      </material>
    </visual>
    <collision>
      <origin xyz="-0 0 0.0025" rpy="0 0 -3.14159" />
      <geometry>
        <mesh filename="assets/dm_j8006_2ec_v1_1__3.stl" />
      </geometry>
    </collision>
  </link>

  <link name="l_knee_pitch_link">
    <inertial>
      <origin xyz="-1.52148e-05 0.125634 0.00177693" rpy="0 0 0" />
      <mass value="0.6749" />
      <inertia ixx="0.00159513" ixy="7.15674e-07" ixz="-1.7921e-07" iyy="0.00039154" iyz="-0.000132758" izz="0.00184146" />
    </inertial>

    <visual>
      <origin xyz="-0 0.16 0.018" rpy="3.14159 0 2.61799" />
      <geometry>
        <mesh filename="assets/part_2__3.stl" />
      </geometry>
      <material name="part_2_5_material">
        <color rgba="0.784314 0.0392157 0.0392157 1" />
      </material>
    </visual>
    <collision>
      <origin xyz="-0 0.16 0.018" rpy="3.14159 0 2.61799" />
      <geometry>
        <mesh filename="assets/part_2__3.stl" />
      </geometry>
    </collision>

    <visual>
      <origin xyz="-0 0.16 0.018" rpy="3.14159 0 2.61799" />
      <geometry>
        <mesh filename="assets/dm_j6006_2ec.stl" />
      </geometry>
      <material name="dm_j6006_2ec_2_material">
        <color rgba="0.301961 0.301961 0.301961 1" />
      </material>
    </visual>
    <collision>
      <origin xyz="-0 0.16 0.018" rpy="3.14159 0 2.61799" />
      <geometry>
        <mesh filename="assets/dm_j6006_2ec.stl" />
      </geometry>
    </collision>
  </link>

  <link name="l_ankle_pitch_link">
    <inertial>
      <origin xyz="0 0.0388582 -0.00340315" rpy="0 0 0" />
      <mass value="0.20135" />
      <inertia ixx="0.000100178" ixy="0" ixz="0" iyy="0.000265009" iyz="1.93066e-05" izz="0.000311964" />
    </inertial>

    <visual>
      <origin xyz="-0 -0.000137091 -0.0015" rpy="-3.14159 0 3.14159" />
      <geometry>
        <mesh filename="assets/part_1__4.stl" />
      </geometry>
      <material name="part_1_8_material">
        <color rgba="0.831373 0.686275 0.215686 1" />
      </material>
    </visual>
    <collision>
      <origin xyz="-0 -0.000137091 -0.0015" rpy="-3.14159 0 3.14159" />
      <geometry>
        <mesh filename="assets/part_1__4.stl" />
      </geometry>
    </collision>
  </link>

  <joint name="l_ankle_pitch" type="revolute">
    <origin xyz="6.85453e-05 0.160119 0.0195" rpy="0 -0 -0" />
    <parent link="l_knee_pitch_link" />
    <child link="l_ankle_pitch_link" />
    <axis xyz="0 0 1" />
    <limit effort="10" velocity="10" lower="-0.523599" upper="0.523599" />
  </joint>

  <joint name="l_knee_pitch" type="revolute">
    <origin xyz="-0 0.12 -0" rpy="-0 0 0" />
    <parent link="l_hip_pitch_link" />
    <child link="l_knee_pitch_link" />
    <axis xyz="0 0 1" />
    <limit effort="10" velocity="10" lower="-1.74533" upper="0" />
  </joint>

  <joint name="l_hip_pitch" type="revolute">
    <origin xyz="0.082 5.91774e-05 0.00460127" rpy="3.14159 -1.5708 0" />
    <parent link="l_hip_roll_link" />
    <child link="l_hip_pitch_link" />
    <axis xyz="0 0 1" />
    <limit effort="10" velocity="10" lower="-0.523599" upper="0.872665" />
  </joint>

  <joint name="l_hip_roll" type="revolute">
    <origin xyz="0.0195 -0.000905374 -0.071579" rpy="1.5708 -0 1.5708" />
    <parent link="l_hip_yaw_link" />
    <child link="l_hip_roll_link" />
    <axis xyz="0 0 1" />
    <limit effort="10" velocity="10" lower="-0.349066" upper="0.349066" />
  </joint>

  <joint name="l_hip_yaw" type="revolute">
    <origin xyz="0.000993584 0.0599212 -0.0215" rpy="0 0 0" />
    <parent link="base_link" />
    <child link="l_hip_yaw_link" />
    <axis xyz="0 0 1" />
    <limit effort="10" velocity="10" lower="-0.523599" upper="0.523599" />
  </joint>
</robot>
