<?xml version="1.0" ?>
<!-- Generated using onshape-to-robot -->
<!-- Onshape https://cad.onshape.com/documents/1ba0590d9c30dce016cf6a88/w/a6739e4b1d1c5be1c5b79663/e/bed74cb9519e3eabc367256a -->
<robot name="robot">
  <!-- Link base_link -->
  <link name="base_link">
    <inertial>
      <origin xyz="-2.19039e-05 5e-12 0.0112116" rpy="0 0 0"/>
      <mass value="0.701657"/>
      <inertia ixx="0.000758294" ixy="-2.07934e-06" ixz="1.39259e-07" iyy="0.000758197" iyz="-0" izz="0.00109167"/>
    </inertial>
    <!-- Part st3215 -->
    <visual>
      <origin xyz="-0.00953491 0.0375 0.00948917" rpy="-3.14159 1.56207 1.0102e-08"/>
      <geometry>
        <mesh filename="package://robot/assets/st3215.stl"/>
      </geometry>
      <material name="st3215_material">
        <color rgba="0.917647 0.917647 0.917647 1"/>
      </material>
    </visual>
    <collision>
      <origin xyz="-0.00953491 0.0375 0.00948917" rpy="-3.14159 1.56207 1.0102e-08"/>
      <geometry>
        <mesh filename="package://robot/assets/st3215.stl"/>
      </geometry>
    </collision>
    <!-- Part st3215_2 -->
    <visual>
      <origin xyz="-0.0277585 -0.0271888 0.00948917" rpy="3.14159 1.56207 2.0944"/>
      <geometry>
        <mesh filename="package://robot/assets/st3215.stl"/>
      </geometry>
      <material name="st3215_2_material">
        <color rgba="0.917647 0.917647 0.917647 1"/>
      </material>
    </visual>
    <collision>
      <origin xyz="-0.0277585 -0.0271888 0.00948917" rpy="3.14159 1.56207 2.0944"/>
      <geometry>
        <mesh filename="package://robot/assets/st3215.stl"/>
      </geometry>
    </collision>
    <!-- Part base_link -->
    <visual>
      <origin xyz="0 7e-12 -0.006" rpy="8.8e-11 -0 1e-12"/>
      <geometry>
        <mesh filename="package://robot/assets/base_link.stl"/>
      </geometry>
      <material name="base_link_material">
        <color rgba="0.301961 0.301961 0.301961 1"/>
      </material>
    </visual>
    <collision>
      <origin xyz="0 7e-12 -0.006" rpy="8.8e-11 -0 1e-12"/>
      <geometry>
        <mesh filename="package://robot/assets/base_link.stl"/>
      </geometry>
    </collision>
    <!-- Part st3215_3 -->
    <visual>
      <origin xyz="0.0371934 -0.0103112 0.00948917" rpy="3.14159 1.56207 -2.0944"/>
      <geometry>
        <mesh filename="package://robot/assets/st3215.stl"/>
      </geometry>
      <material name="st3215_3_material">
        <color rgba="0.917647 0.917647 0.917647 1"/>
      </material>
    </visual>
    <collision>
      <origin xyz="0.0371934 -0.0103112 0.00948917" rpy="3.14159 1.56207 -2.0944"/>
      <geometry>
        <mesh filename="package://robot/assets/st3215.stl"/>
      </geometry>
    </collision>
  </link>
  <!-- Link rod_1 -->
  <link name="leg1_upper">
    <inertial>
      <origin xyz="-0.0280003 -0 0" rpy="0 0 0"/>
      <mass value="0.0266055"/>
      <inertia ixx="8.56598e-06" ixy="0" ixz="-0" iyy="1.88629e-05" iyz="0" izz="1.30613e-05"/>
    </inertial>
    <!-- Part rod_1 -->
    <visual>
      <origin xyz="-0.0495492 -0.0125 0" rpy="-1.5708 -1.5708 0"/>
      <geometry>
        <mesh filename="package://robot/assets/rod_1.stl"/>
      </geometry>
      <material name="rod_1_material">
        <color rgba="0.972549 0.529412 0.00392157 1"/>
      </material>
    </visual>
    <collision>
      <origin xyz="-0.0495492 -0.0125 0" rpy="-1.5708 -1.5708 0"/>
      <geometry>
        <mesh filename="package://robot/assets/rod_1.stl"/>
      </geometry>
    </collision>
    <!-- Part rod_1_2 -->
    <visual>
      <origin xyz="-0.0495492 0.0125 -0" rpy="1.5708 1.5708 0"/>
      <geometry>
        <mesh filename="package://robot/assets/rod_1.stl"/>
      </geometry>
      <material name="rod_1_2_material">
        <color rgba="0.972549 0.529412 0.00392157 1"/>
      </material>
    </visual>
    <collision>
      <origin xyz="-0.0495492 0.0125 -0" rpy="1.5708 1.5708 0"/>
      <geometry>
        <mesh filename="package://robot/assets/rod_1.stl"/>
      </geometry>
    </collision>
  </link>
  <!-- Link rod_2 -->
  <link name="leg1_lower">
    <inertial>
      <origin xyz="0.0325254 -0 -0" rpy="0 0 0"/>
      <mass value="0.0295146"/>
      <inertia ixx="1.5431e-06" ixy="-0" ixz="0" iyy="2.72758e-05" iyz="0" izz="2.82494e-05"/>
    </inertial>
    <!-- Part rod_2 -->
    <visual>
      <origin xyz="-0 0 -0" rpy="-1.5708 -1.5708 0"/>
      <geometry>
        <mesh filename="package://robot/assets/rod_2.stl"/>
      </geometry>
      <material name="rod_2_material">
        <color rgba="0.972549 0.529412 0.00392157 1"/>
      </material>
    </visual>
    <collision>
      <origin xyz="-0 0 -0" rpy="-1.5708 -1.5708 0"/>
      <geometry>
        <mesh filename="package://robot/assets/rod_2.stl"/>
      </geometry>
    </collision>
  </link>
  <!-- Link plate -->
  <link name="platform">
    <inertial>
      <origin xyz="-0.0575484 -1.55756e-05 0" rpy="0 0 0"/>
      <mass value="0.0924122"/>
      <inertia ixx="6.24868e-05" ixy="1.8062e-08" ixz="0" iyy="0.000123663" iyz="0" izz="6.2414e-05"/>
    </inertial>
    <!-- Part plate -->
    <visual>
      <origin xyz="-0.0575 -0.0045 0" rpy="-1.5708 -1.5708 0"/>
      <geometry>
        <mesh filename="package://robot/assets/plate.stl"/>
      </geometry>
      <material name="plate_material">
        <color rgba="0.196078 0.188235 0.188235 1"/>
      </material>
    </visual>
    <collision>
      <origin xyz="-0.0575 -0.0045 0" rpy="-1.5708 -1.5708 0"/>
      <geometry>
        <mesh filename="package://robot/assets/plate.stl"/>
      </geometry>
    </collision>
  </link>
  <!-- Frame tracking (dummy link + fixed joint) -->
  <link name="tracking">
    <inertial>
      <origin xyz="0 0 0" rpy="0 0 0"/>
      <mass value="1e-9"/>
      <inertia ixx="1e-12" ixy="0" ixz="0" iyy="1e-12" iyz="0" izz="1e-12"/>
    </inertial>
  </link>
  <joint name="tracking_frame" type="fixed">
    <origin xyz="-0.056 0.0045 0" rpy="-1.5708 -0 0"/>
    <parent link="platform"/>
    <child link="tracking"/>
    <axis xyz="0 0 0"/>
  </joint>
  <!-- Frame closing_leg2_ball_1 (dummy link + fixed joint) -->
  <link name="closing_leg2_ball_1">
    <inertial>
      <origin xyz="0 0 0" rpy="0 0 0"/>
      <mass value="1e-9"/>
      <inertia ixx="1e-12" ixy="0" ixz="0" iyy="1e-12" iyz="0" izz="1e-12"/>
    </inertial>
  </link>
  <joint name="closing_leg2_ball_1_frame" type="fixed">
    <origin xyz="-0.08625 0 0.0497965" rpy="1.5708 -1.0472 -3.14159"/>
    <parent link="platform"/>
    <child link="closing_leg2_ball_1"/>
    <axis xyz="0 0 0"/>
  </joint>
  <!-- Frame closing_leg3_ball_1 (dummy link + fixed joint) -->
  <link name="closing_leg3_ball_1">
    <inertial>
      <origin xyz="0 0 0" rpy="0 0 0"/>
      <mass value="1e-9"/>
      <inertia ixx="1e-12" ixy="0" ixz="0" iyy="1e-12" iyz="0" izz="1e-12"/>
    </inertial>
  </link>
  <joint name="closing_leg3_ball_1_frame" type="fixed">
    <origin xyz="-0.08625 0 -0.0497965" rpy="1.5708 1.0472 -3.14159"/>
    <parent link="platform"/>
    <child link="closing_leg3_ball_1"/>
    <axis xyz="0 0 0"/>
  </joint>
  <!-- leg1 spherical joint approximation: Z-Y-X revolute chain -->
  <link name="leg1_ball_z_link">
    <inertial>
      <origin xyz="0 0 0" rpy="0 0 0"/>
      <mass value="1e-9"/>
      <inertia ixx="1e-12" ixy="0" ixz="0" iyy="1e-12" iyz="0" izz="1e-12"/>
    </inertial>
  </link>
  <link name="leg1_ball_y_link">
    <inertial>
      <origin xyz="0 0 0" rpy="0 0 0"/>
      <mass value="1e-9"/>
      <inertia ixx="1e-12" ixy="0" ixz="0" iyy="1e-12" iyz="0" izz="1e-12"/>
    </inertial>
  </link>
  <joint name="leg1_ball_z" type="revolute">
    <origin xyz="0.114 0 0" rpy="0.00716805 0.0291991 -1.92504"/>
    <parent link="leg1_lower"/>
    <child link="leg1_ball_z_link"/>
    <axis xyz="0 0 1"/>
    <limit effort="10" velocity="10" lower="-3.141592653589793" upper="3.141592653589793"/>
  </joint>
  <joint name="leg1_ball_y" type="revolute">
    <origin xyz="0 0 0" rpy="0 0 0"/>
    <parent link="leg1_ball_z_link"/>
    <child link="leg1_ball_y_link"/>
    <axis xyz="0 1 0"/>
    <limit effort="10" velocity="10" lower="-3.141592653589793" upper="3.141592653589793"/>
  </joint>
  <joint name="leg1_ball_x" type="revolute">
    <origin xyz="0 0 0" rpy="0 0 0"/>
    <parent link="leg1_ball_y_link"/>
    <child link="platform"/>
    <axis xyz="1 0 0"/>
    <limit effort="10" velocity="10" lower="-3.141592653589793" upper="3.141592653589793"/>
  </joint>
  <!-- Joint from rod_1 to rod_2 -->
  <joint name="leg1_2" type="revolute">
    <origin xyz="-0.0595492 -0 0" rpy="0 0 -1.21629"/>
    <parent link="leg1_upper"/>
    <child link="leg1_lower"/>
    <axis xyz="0 0 1"/>
    <limit effort="10" velocity="10" lower="-3.141592653589793" upper="3.141592653589793"/>
  </joint>
  <!-- Joint from base_link to rod_1 -->
  <joint name="leg1_1" type="revolute">
    <origin xyz="-0.000657784 0.0375 0.0350676" rpy="-1.56207 8.8e-11 -1.5708"/>
    <parent link="base_link"/>
    <child link="leg1_upper"/>
    <axis xyz="0 0 1"/>
    <limit effort="10" velocity="10" lower="0" upper="1.5708"/>
  </joint>
  <!-- Link rod_1_2 -->
  <link name="leg2_upper">
    <inertial>
      <origin xyz="-0.0280003 0 -0" rpy="0 0 0"/>
      <mass value="0.0266055"/>
      <inertia ixx="8.56598e-06" ixy="0" ixz="-0" iyy="1.88629e-05" iyz="0" izz="1.30613e-05"/>
    </inertial>
    <!-- Part rod_1_3 -->
    <visual>
      <origin xyz="-0.0495492 -0.0125 -0" rpy="-1.5708 -1.5708 0"/>
      <geometry>
        <mesh filename="package://robot/assets/rod_1.stl"/>
      </geometry>
      <material name="rod_1_3_material">
        <color rgba="0.972549 0.529412 0.00392157 1"/>
      </material>
    </visual>
    <collision>
      <origin xyz="-0.0495492 -0.0125 -0" rpy="-1.5708 -1.5708 0"/>
      <geometry>
        <mesh filename="package://robot/assets/rod_1.stl"/>
      </geometry>
    </collision>
    <!-- Part rod_1_4 -->
    <visual>
      <origin xyz="-0.0495492 0.0125 -0" rpy="1.5708 1.5708 0"/>
      <geometry>
        <mesh filename="package://robot/assets/rod_1.stl"/>
      </geometry>
      <material name="rod_1_4_material">
        <color rgba="0.972549 0.529412 0.00392157 1"/>
      </material>
    </visual>
    <collision>
      <origin xyz="-0.0495492 0.0125 -0" rpy="1.5708 1.5708 0"/>
      <geometry>
        <mesh filename="package://robot/assets/rod_1.stl"/>
      </geometry>
    </collision>
  </link>
  <!-- Link rod_2_2 -->
  <link name="leg2_lower">
    <inertial>
      <origin xyz="0.0325254 0 -0" rpy="0 0 0"/>
      <mass value="0.0295146"/>
      <inertia ixx="1.5431e-06" ixy="-0" ixz="-0" iyy="2.72758e-05" iyz="-0" izz="2.82494e-05"/>
    </inertial>
    <!-- Part rod_2_2 -->
    <visual>
      <origin xyz="0 0 -0" rpy="-1.5708 -1.5708 0"/>
      <geometry>
        <mesh filename="package://robot/assets/rod_2.stl"/>
      </geometry>
      <material name="rod_2_2_material">
        <color rgba="0.972549 0.529412 0.00392157 1"/>
      </material>
    </visual>
    <collision>
      <origin xyz="0 0 -0" rpy="-1.5708 -1.5708 0"/>
      <geometry>
        <mesh filename="package://robot/assets/rod_2.stl"/>
      </geometry>
    </collision>
  </link>
  <!-- Frame closing_leg3_ball_2 (dummy link + fixed joint) -->
  <link name="closing_leg3_ball_2">
    <inertial>
      <origin xyz="0 0 0" rpy="0 0 0"/>
      <mass value="1e-9"/>
      <inertia ixx="1e-12" ixy="0" ixz="0" iyy="1e-12" iyz="0" izz="1e-12"/>
    </inertial>
  </link>
  <joint name="closing_leg3_ball_2_frame" type="fixed">
    <origin xyz="0.114 0 -0" rpy="-1.5708 0 -1.5708"/>
    <parent link="leg2_lower"/>
    <child link="closing_leg3_ball_2"/>
    <axis xyz="0 0 0"/>
  </joint>
  <!-- Joint from rod_1_2 to rod_2_2 -->
  <joint name="leg2_2" type="revolute">
    <origin xyz="-0.0595492 0 -0" rpy="-0 0 -1.21431"/>
    <parent link="leg2_upper"/>
    <child link="leg2_lower"/>
    <axis xyz="0 0 1"/>
    <limit effort="10" velocity="10" lower="-3.141592653589793" upper="3.141592653589793"/>
  </joint>
  <!-- Joint from base_link to rod_1_2 -->
  <joint name="leg2_1" type="revolute">
    <origin xyz="-0.0321971 -0.019501 0.0350676" rpy="-1.56207 -4.4e-11 0.523599"/>
    <parent link="base_link"/>
    <child link="leg2_upper"/>
    <axis xyz="0 0 1"/>
    <limit effort="10" velocity="10" lower="0" upper="1.5708"/>
  </joint>
  <!-- Link rod_1_3 -->
  <link name="leg3_upper">
    <inertial>
      <origin xyz="-0.0280003 -0 0" rpy="0 0 0"/>
      <mass value="0.0266055"/>
      <inertia ixx="8.56598e-06" ixy="0" ixz="0" iyy="1.88629e-05" iyz="0" izz="1.30613e-05"/>
    </inertial>
    <!-- Part rod_1_5 -->
    <visual>
      <origin xyz="-0.0495492 0.0125 -0" rpy="1.5708 1.5708 0"/>
      <geometry>
        <mesh filename="package://robot/assets/rod_1.stl"/>
      </geometry>
      <material name="rod_1_5_material">
        <color rgba="0.972549 0.529412 0.00392157 1"/>
      </material>
    </visual>
    <collision>
      <origin xyz="-0.0495492 0.0125 -0" rpy="1.5708 1.5708 0"/>
      <geometry>
        <mesh filename="package://robot/assets/rod_1.stl"/>
      </geometry>
    </collision>
    <!-- Part rod_1_6 -->
    <visual>
      <origin xyz="-0.0495492 -0.0125 0" rpy="-1.5708 -1.5708 0"/>
      <geometry>
        <mesh filename="package://robot/assets/rod_1.stl"/>
      </geometry>
      <material name="rod_1_6_material">
        <color rgba="0.972549 0.529412 0.00392157 1"/>
      </material>
    </visual>
    <collision>
      <origin xyz="-0.0495492 -0.0125 0" rpy="-1.5708 -1.5708 0"/>
      <geometry>
        <mesh filename="package://robot/assets/rod_1.stl"/>
      </geometry>
    </collision>
  </link>
  <!-- Link rod_2_3 -->
  <link name="leg3_lower">
    <inertial>
      <origin xyz="0.0325254 -0 -0" rpy="0 0 0"/>
      <mass value="0.0295146"/>
      <inertia ixx="1.5431e-06" ixy="-0" ixz="-0" iyy="2.72758e-05" iyz="0" izz="2.82494e-05"/>
    </inertial>
    <!-- Part rod_2_3 -->
    <visual>
      <origin xyz="0 0 -0" rpy="-1.5708 -1.5708 0"/>
      <geometry>
        <mesh filename="package://robot/assets/rod_2.stl"/>
      </geometry>
      <material name="rod_2_3_material">
        <color rgba="0.972549 0.529412 0.00392157 1"/>
      </material>
    </visual>
    <collision>
      <origin xyz="0 0 -0" rpy="-1.5708 -1.5708 0"/>
      <geometry>
        <mesh filename="package://robot/assets/rod_2.stl"/>
      </geometry>
    </collision>
  </link>
  <!-- Frame closing_leg2_ball_2 (dummy link + fixed joint) -->
  <link name="closing_leg2_ball_2">
    <inertial>
      <origin xyz="0 0 0" rpy="0 0 0"/>
      <mass value="1e-9"/>
      <inertia ixx="1e-12" ixy="0" ixz="0" iyy="1e-12" iyz="0" izz="1e-12"/>
    </inertial>
  </link>
  <joint name="closing_leg2_ball_2_frame" type="fixed">
    <origin xyz="0.114 0 -0" rpy="-1.5708 0 -1.5708"/>
    <parent link="leg3_lower"/>
    <child link="closing_leg2_ball_2"/>
    <axis xyz="0 0 0"/>
  </joint>
  <!-- Joint from rod_1_3 to rod_2_3 -->
  <joint name="leg3_2" type="revolute">
    <origin xyz="-0.0595492 0 0" rpy="0 -0 -1.21824"/>
    <parent link="leg3_upper"/>
    <child link="leg3_lower"/>
    <axis xyz="0 0 1"/>
    <limit effort="10" velocity="10" lower="-3.141592653589793" upper="3.141592653589793"/>
  </joint>
  <!-- Joint from base_link to rod_1_3 -->
  <joint name="leg3_1" type="revolute">
    <origin xyz="0.0327548 -0.017999 0.0350676" rpy="-1.56207 -4.4e-11 2.61799"/>
    <parent link="base_link"/>
    <child link="leg3_upper"/>
    <axis xyz="0 0 1"/>
    <limit effort="10" velocity="10" lower="0" upper="1.5708"/>
  </joint>
</robot>
